<?xml version="1.0"?>
<robot xmlns:xacro="http://www.ros.org/wiki/xacro" name="rockbreaker_arm">
  <xacro:arg name="gpu" default="false"/>
  <xacro:property name="gpu" value="$(arg gpu)" />
  <xacro:arg name="organize_cloud" default="false"/>
  <xacro:property name="organize_cloud" value="$(arg organize_cloud)" />
  <xacro:property name="M_PI" value="3.1415926535897931" />

   <!-- Import all Gazebo-customization elements, including Gazebo colors -->
  <!-- <xacro:include filename="$(find rockbreaker_arm_simulator)/rockbreaker_arm_simulator/rockbreaker_description/urdf/rockbreaker_arm.gazebo" /> -->

  <xacro:macro name="box_inertia" params="x y z mass">
    <!-- <inertial> -->
      <!-- <mass value="${mass}" /> -->
      <inertia ixx="${0.0833333 * mass * (y*y + z*z)}" ixy="0.0" ixz="0.0"
               iyy="${0.0833333 * mass * (x*x + z*z)}" iyz="0.0"
               izz="${0.0833333 * mass * (x*x + y*y)}" />
    <!-- </inertial> -->
  </xacro:macro>


 <!-- Base Fija -->
  <link name="base_fija" />

  <!-- Base Link -->
  <joint name="Fija" type="fixed" >
    <parent link="base_fija" />
    <child link="rockbreaker_base" />
    <origin xyz="0 0 0.0" rpy="0 0 0" />
  </joint>

  <!-- Base Fija -->
  <link name="rockbreaker_base" >
    <visual>
      <origin xyz="0 0 -0.4" rpy="0 0 0"/>
      <geometry>
        <!--<mesh filename = "file:///home/kyungki/workspace/catkin_ws/src/velodyne_simulator/velodyne_description/meshes/excavator-1.dae"/>-->
        <mesh filename="package://rockbreaker_arm_simulator/rockbreaker_description/meshes/base_fija.stl" scale="0.1 0.1 0.1"/>
      </geometry>
    </visual>
    <collision>
      <origin xyz="0 0 1.5" rpy="0 0 0"/>
      <geometry>
        <box size="14 12 3"/>
      </geometry>
    </collision>
    <inertial>
      <origin xyz="0 0 1.5"/>
      <mass value="100"/>
      <xacro:box_inertia x="14" y="12" z="3" mass="100"/>
    </inertial>
  </link>
  <!-- Base Giratoria -->
  <link name="rockbreaker_basegiratoria" >
    <visual>
      <origin xyz="0 0 1.4" rpy="0 0 0"/>
      <geometry>
        <!--<mesh filename = "file:///home/kyungki/workspace/catkin_ws/src/velodyne_simulator/velodyne_description/meshes/excavator-1.dae"/>-->
        <mesh filename="package://rockbreaker_arm_simulator/rockbreaker_description/meshes/base_giratoria.stl" scale="0.1 0.1 0.1"/>
      </geometry>
    </visual>
    <collision>
      <origin xyz="0 0 5" rpy="0 0 0"/>
      <geometry>
        <box size="4 12 4"/>
      </geometry>
    </collision>
    <inertial>
      <origin xyz="0 0 5"/>
      <mass value="40"/>
      <inertia ixx="3.0" ixy="0.0" ixz="0.0"
               iyy="3.0" iyz="0.0" 
               izz="3.0" />
    </inertial>
  </link>

  <!-- Brazo A -->
  <link name="brazo_a" >
    <visual>
      <origin xyz="-0.9 0 0.1" rpy="0 0 0"/>
      <geometry>
        <!--<mesh filename = "file:///home/kyungki/workspace/catkin_ws/src/velodyne_simulator/velodyne_description/meshes/excavator-1.dae"/>-->
        <mesh filename="package://rockbreaker_arm_simulator/rockbreaker_description/meshes/rockbreaker-brazo_a.stl" scale="0.1 0.1 0.1"/>
      </geometry>
    </visual>
    <collision>
      <origin xyz="-7.4 0 7.0" rpy="0 0.65 0"/>
      <geometry>
        <box size="14 1.5 1.0"/>
      </geometry>
    </collision>
    <inertial>
      <origin xyz="-7.4 0 7.0"/>
      <mass value="20"/>
      <inertia ixx="3.0" ixy="0.0" ixz="0.0"
               iyy="3.0" iyz="0.0" 
               izz="3.0" />
    </inertial>
  </link>

  <!-- Brazo B -->
  <link name="brazo_b" >
    <visual>
      <origin xyz="-0.0 0 -0.4" rpy="0 0 0"/>
      <geometry>
        <!--<mesh filename = "file:///home/kyungki/workspace/catkin_ws/src/velodyne_simulator/velodyne_description/meshes/excavator-1.dae"/>-->
        <mesh filename="package://rockbreaker_arm_simulator/rockbreaker_description/meshes/rockbrekear-brazo_b.stl" scale="0.1 0.1 0.1"/>
      </geometry>
    </visual>
    <collision>
      <origin xyz="-3.0 0 -7.0" rpy="0 2.0 0"/>
      <geometry>
        <box size="12 1.0 1.0"/>
      </geometry>
    </collision>
    <inertial>
      <origin xyz="-3.0 0 -7.0"/>
      <mass value="10"/>
      <inertia ixx="3.0" ixy="0.0" ixz="0.0"
               iyy="3.0" iyz="0.0" 
               izz="3.0" />
    </inertial>
  </link>

    <!-- Hydraulic Hammer -->
  <link name="hydraulic_hammer" >
    <visual>
      <origin xyz="-0.16 0 -0.0" rpy="0 0 0"/>
      <geometry>
        <!--<mesh filename = "file:///home/kyungki/workspace/catkin_ws/src/velodyne_simulator/velodyne_description/meshes/excavator-1.dae"/>-->
        <mesh filename="package://rockbreaker_arm_simulator/rockbreaker_description/meshes/rockbreaker-hydraulic_hammer.stl" scale="0.1 0.1 0.1"/>
      </geometry>
    </visual>
    <collision>
      <origin xyz="0 0 0" rpy="0 0 0"/>
      <geometry>
        <box size="2 6 0.2"/>
      </geometry>
    </collision>
    <inertial>
      <origin xyz="0 0 0"/>
      <mass value="5"/>
      <inertia ixx="3.0" ixy="0.0" ixz="0.0"
               iyy="3.0" iyz="0.0" 
               izz="3.0" />
    </inertial>
  </link>

   <!-- Hydraulic Hammer Punta -->
  <link name="punta" >
    <visual>
      <origin xyz="-0.16 0 -0.0" rpy="0 0 0"/>
      <geometry>
        <!--<mesh filename = "file:///home/kyungki/workspace/catkin_ws/src/velodyne_simulator/velodyne_description/meshes/excavator-1.dae"/>-->
        <mesh filename="package://rockbreaker_arm_simulator/rockbreaker_description/meshes/hydraulic-hammer_punta.stl" scale="0.1 0.1 0.1"/>
      </geometry>
    </visual>
    <collision>
      <origin xyz="0 0 0" rpy="0 0 0"/>
      <geometry>
        <box size="2 6 0.2"/>
      </geometry>
    </collision>
    <inertial>
      <origin xyz="0 0 0"/>
      <mass value="5"/>
      <inertia ixx="3.0" ixy="0.0" ixz="0.0"
               iyy="3.0" iyz="0.0" 
               izz="3.0" />
    </inertial>
  </link>

  <joint name="joint_base_yaw" type="revolute" >
    <axis xyz="0 0 1"/>
    <limit effort="1000.0" lower="0.0" upper="1.57" velocity="10.0"/>
    <parent link="rockbreaker_base" />
    <child link="rockbreaker_basegiratoria" />
    <origin xyz="0 0 2.0" rpy="0 0 0" />
  </joint>

  <joint name="joint_arm_1" type="revolute" >
    <axis xyz="0 1 0"/>
    <limit effort="100000.0" lower="0.0" upper="3.1415" velocity="10000.0"/>
    <parent link="rockbreaker_basegiratoria" />
    <child link="arm_1" />
    <origin xyz="0.2 0 5.6" rpy="0 0 0" /> 
  </joint>

  <joint name="joint_brazo_b" type="revolute" >
    <axis xyz="0 1 0"/>
    <limit effort="100000.0" lower="0.0" upper="3.1415" velocity="10000.0"/>
    <parent link="arm_1" />
    <child link="brazo_b" />
    <origin xyz="-18.0 0 14.4" rpy="0 0 0" /> 
  </joint>

  <joint name="joint_arm_3" type="revolute" >
    <axis xyz="0 1 0"/>
    <limit effort="100000.0" lower="0.0" upper="3.1415" velocity="10000.0"/>
    <parent link="brazo_b" />
    <child link="arm_3" />
    <origin xyz="-7.0 0 -16" rpy="0 0 0" /> 
  </joint>

  <transmission name="tran1">
    <type>transmission_interface/SimpleTransmission</type>
    <joint name="joint_arm_1">
      <hardwareInterface>hardware_interface/EffortJointInterface</hardwareInterface>
    </joint>
    <actuator name="motor1">
      <hardwareInterface>hardware_interface/EffortJointInterface</hardwareInterface>
      <mechanicalReduction>1</mechanicalReduction>
    </actuator>
  </transmission>

  <transmission name="tran2">
    <type>transmission_interface/SimpleTransmission</type>
    <joint name="joint_brazo_b">
      <hardwareInterface>hardware_interface/EffortJointInterface</hardwareInterface>
    </joint>
    <actuator name="motor2">
      <hardwareInterface>hardware_interface/EffortJointInterface</hardwareInterface>
      <mechanicalReduction>1</mechanicalReduction>
    </actuator>
  </transmission>

  <transmission name="tran3">
    <type>transmission_interface/SimpleTransmission</type>
    <joint name="joint_arm_3">
      <hardwareInterface>hardware_interface/EffortJointInterface</hardwareInterface>
    </joint>
    <actuator name="motor3">
      <hardwareInterface>hardware_interface/EffortJointInterface</hardwareInterface>
      <mechanicalReduction>1</mechanicalReduction>
    </actuator>
  </transmission>

  <!--
  <xacro:include filename="$(find velodyne_description)/urdf/VLP-16.urdf.xacro"/>
  <xacro:VLP-16 parent="excavator_base" name="velodyne" topic="/velodyne_points" organize_cloud="${organize_cloud}" hz="10" samples="440" gpu="${gpu}" >
    <origin xyz="1 2.7 1.2" rpy="0 0 0" />
  </xacro:VLP-16>
  -->

  <!-- <xacro:include filename=rockbreaker)/urdf/HDL-32E.urdf.xacro"/> -->
  <!--<xacro:include filename="$(find velodyne_description)/urdf/camera.urdf.xacro"/>-->
  <!-- <xacro:include filename=rockbreaker)/urdf/stereo_camera.urdf.xacro"/>
  <xacro:include filename=rockbreaker)/urdf/VLP-16.urdf.xacro"/>

  <xacro:stereo_camera_sensor parent="excavator_base" name="camera_front" >
    <origin xyz="0.8 0 1.5" rpy="0 0 ${-M_PI}" />
  </xacro:stereo_camera_sensor> -->
 
  <!--
  <xacro:HDL-32E parent="excavator_base" name="velodyne_top" topic="/top/velodyne_points2" organize_cloud="${organize_cloud}" hz="10" samples="220" min_angle="${-M_PI}" max_angle="${M_PI}" gpu="${gpu}" >
    <origin xyz="0 0 2.8" rpy="0 0 0" />
  </xacro:HDL-32E>

  <xacro:camera_sensor parent="excavator_base" name="camera_left_front" >
    <origin xyz="-0.8 2.7 1.2" rpy="0 0 ${M_PI/2}" />
  </xacro:camera_sensor>

  

  <xacro:camera_sensor parent="excavator_base" name="camera_left_back" >
    <origin xyz="-0.8 -3 1.2" rpy="0 0 ${-M_PI/2}" />
  </xacro:camera_sensor>

  <xacro:camera_sensor parent="excavator_base" name="camera_right_back" >
    <origin xyz="0.8 -3 1.2" rpy="0 0 ${-M_PI/2}" />
  </xacro:camera_sensor>
  -->
</robot>
